Workbook

Sheet Dashboard
B2: Membership Experience Dashboard
B3: AIESEC in Bengaluru · Membership Experience Survey · April 2024
B5: Show role: | C5: Overall | E5: ◀ pick a role to update the cards and the two charts below
B7: RESPONSES | E7: JOB DESIGN | H7: WELLBEING | K7: COMMUNITY | N7: TEAM PRACTICES | Q7: NPS (ALL)
B8: =INDEX(Data!$B$6:$B$9,MATCH($C$5,Data!$A$6:$A$9,0)) -> 99 | E8: =INDEX(Data!$B$66:$E$66,MATCH($C$5,Data!$B$65:$E$65,0)) -> 0.821 | H8: =INDEX(Data!$B$67:$E$67,MATCH($C$5,Data!$B$65:$E$65,0)) -> 0.908 | K8: =INDEX(Data!$B$68:$E$68,MATCH($C$5,Data!$B$65:$E$65,0)) -> 0.856 | N8: =INDEX(Data!$B$69:$E$69,MATCH($C$5,Data!$B$65:$E$65,0)) -> 0.843925 | Q8: =(SUMIF(Data!$C$52:$C$61,"Promoter",Data!$B$52:$B$61)-SUMIF(Data!$C$52:$C$61,"Detractor",Data!$B$52:$B$61))/SUM(Data!$B$52:$B$61)*100 -> 39.393939
B10: members surveyed | E10: clarity & support | H10: workplace & wellbeing | K10: community engagement | N10: building to development | Q10: promoters minus detractors
B11: ="Average recommendation score: "&TEXT(SUMPRODUCT(Data!$A$52:$A$61,Data!$B$52:$B$61)/SUM(Data!$B$52:$B$61),"0.00")&" / 10" -> Average recommendation score: 8.21 / 10
B13: EXPERIENCE BY ROLE (changes with the dropdown)
B30: HEATMAP: EXPERIENCE SCORE BY ROLE | N30: KEY INSIGHTS
B31: Area | E31: Team Members | G31: Team Leaders | I31: Vice-Presidents | K31: Overall | N31: 1. Members would recommend AIESEC: NPS of +39, with 52 of 99 scoring 9 or 10.
B32: Job Design & Support | E32: =Data!B66 -> 0.821 | G32: =Data!C66 -> 0.88888889 | I32: =Data!D66 -> 0.91111111 | K32: =Data!E66 -> 0.821 | N32: 2. The leadership pipeline is at risk: 36% are unsure about applying. Most interest is in Team Leader roles (35).
B33: Workplace & Wellbeing | E33: =Data!B67 -> 0.825 | G33: =Data!C67 -> 0.91111111 | I33: =Data!D67 -> 0.92222222 | K33: =Data!E67 -> 0.908 | N33: 3. VPs are satisfied but under-supported. Their team development and performance scores (6.6 and 6.9) are the lowest in the survey.
B34: Community Engagement | E34: =Data!B68 -> 0.858 | G34: =Data!C68 -> 0.86666667 | I34: =Data!D68 -> 0.86666667 | K34: =Data!E68 -> 0.856 | N34: 4. People stay for community (33%) and soft skills (30%), so invest in bonding spaces and skills workshops.
B35: Team Practices | E35: =Data!B69 -> 0.851875 | G35: =Data!C69 -> 0.8778 | I35: =Data!D69 -> 0.752775 | K35: =Data!E69 -> 0.843925
B36: Red = weakest, green = strongest. VPs rate Team Practices lowest (75%), driven by Development (6.6/10) and Performance (6.9/10).
B38: LEADERSHIP PIPELINE & MOTIVATION (all respondents)
B55: RECOMMENDATION & MEMBERSHIP MIX
B72: Data rebuilt from the original April 2024 report slides. See the About tab for method and notes.

Sheet Data
A1: Source data: AIESEC in Bengaluru, Membership Experience Survey, April 2024
A2: Blue numbers are typed in from the original report slides. Black numbers are formulas.
A4: 1. Respondents by role
A5: Role | B5: Responses
A6: Team Members | B6: 82
A7: Team Leaders | B7: 8
A8: Vice-Presidents | B8: 9
A9: Overall | B9: =SUM(B6:B8) -> 99
A11: 2. Respondents by portfolio
A12: Portfolio | B12: Responses
A13: Outgoing Global Volunteer | B13: 28
A14: Business Development | B14: 16
A15: Incoming Global Volunteer | B15: 15
A16: Outgoing Global Talent | B16: 13
A17: Incoming Global Teacher | B17: 9
A18: Marketing | B18: 9
A19: Incoming Global Talent | B19: 8
A20: Finance & Legal | B20: 1
A23: 3. Will you apply for a higher role?
A24: Answer | B24: Responses | C24: Share
A25: Applying | B25: 54 | C25: =B25/SUM($B$25:$B$27) -> 0.54545455
A26: Not sure | B26: 36 | C26: =B26/SUM($B$25:$B$27) -> 0.36363636
A27: Not applying | B27: 9 | C27: =B27/SUM($B$25:$B$27) -> 0.090909091
A29: 4. Which leadership role interests you most?
A30: Role of interest | B30: Responses
A31: Team Leader | B31: 35
A32: Vice-President | B32: 14
A33: LC President | B33: 5
A34: AIESEC International | B34: 5
A35: Managers | B35: 4
A36: GST | B36: 3
A37: NST / EST | B37: 3
A38: OC-CC | B38: 2
A39: Not applying | B39: 15
A41: 5. Top reason for staying in AIESEC
A42: Motivator | B42: Responses | C42: Share
A43: Community & people | B43: 33 | C43: =B43/SUM($B$43:$B$47) -> 0.33333333
A44: Soft skills development | B44: 30 | C44: =B44/SUM($B$43:$B$47) -> 0.3030303
A45: Professional development | B45: 22 | C45: =B45/SUM($B$43:$B$47) -> 0.22222222
A46: Connection to the organisation | B46: 9 | C46: =B46/SUM($B$43:$B$47) -> 0.090909091
...

Sheet Calc
A1: Helper ranges for the dashboard charts (driven by the role dropdown). No need to edit.
A3: Selected role | B3: =Dashboard!$C$5 -> Overall
A5: Area | B5: Score
A6: Job Design & Support | B6: =INDEX(Data!$B$66:$E$66,MATCH($B$3,Data!$B$65:$E$65,0)) -> 0.821
A7: Workplace & Wellbeing | B7: =INDEX(Data!$B$67:$E$67,MATCH($B$3,Data!$B$65:$E$65,0)) -> 0.908
A8: Community Engagement | B8: =INDEX(Data!$B$68:$E$68,MATCH($B$3,Data!$B$65:$E$65,0)) -> 0.856
A9: Team Practices | B9: =INDEX(Data!$B$69:$E$69,MATCH($B$3,Data!$B$65:$E$65,0)) -> 0.843925
A11: Practice | B11: Avg score
A12: Team Building | B12: =INDEX(Data!$B$74:$E$74,MATCH($B$3,Data!$B$73:$E$73,0)) -> 8.606
A13: Team Engagement | B13: =INDEX(Data!$B$75:$E$75,MATCH($B$3,Data!$B$73:$E$73,0)) -> 8.394
A14: Team Performance | B14: =INDEX(Data!$B$76:$E$76,MATCH($B$3,Data!$B$73:$E$73,0)) -> 8.414
A15: Team Development | B15: =INDEX(Data!$B$77:$E$77,MATCH($B$3,Data!$B$73:$E$73,0)) -> 8.343

Sheet About
A1: About this dashboard
A2: A one-page dashboard of the AIESEC in Bengaluru Membership Experience Survey (April 2024, 99 responses).
A4: How to use
A5: Pick a role in the dropdown at the top of the Dashboard tab. The KPI cards and the first two charts update automatically.
A7: How the data was rebuilt
A8: The raw form responses were no longer available, so every figure was rebuilt from the original report slides.
A9: • Counts (roles, portfolios, leadership intent, roles of interest, recommendation scores) were copied directly from the slides.
A10: • Team Leader and VP scores were recovered answer by answer. Each pie slice on those slides was one person's score,
A11: and the recovered totals match the headline percentages on the slides (for example, VP Job Design 82/90 = 91.1%).
A12: • Team Member and Overall scores use the headline percentages from the slides. Their pie charts plotted the score values
A13: themselves rather than how many people gave each score, so the distributions can't be recovered.
A15: Corrections to the original report
... A19: Built with: Google Sheets / Excel formulas (INDEX-MATCH, SUMIF, SUMPRODUCT), data validation, conditional formatting.
